Workbook
Name \A: #REF!
Name \i: #N/A
Name \M: #REF!
Name \P: #REF!
Name \q: #REF!
Name \s: #N/A
Name \W: #REF!
Name \x: #REF!
Name _: [0]!galian TANAH
Name _: [0]!galian TANAH
Name _: galian TANAH
Name ____________________________________________________________________________________________A16500: #REF!
Name __________________________________________________________________________________________A16500: #REF!
Name ________________________________________________________________________________________A16500: #REF!
Name ______________________________________________________________________________________A16500: #REF!
Name ____________________________________________________________________________________A16500: #REF!
Name __________________________________________________________________________________A16500: #REF!
Name ________________________________________________________________________________A16500: #REF!
Name ______________________________________________________________________________A16500: #REF!
Name ____________________________________________________________________________A16500: #REF!
Name __________________________________________________________________________A16500: #REF!
Name ___________________________________________________________________A16500: #REF!
Name ____________________________________________________________A16500: #REF!
Name ________________________________________________________A16500: #REF!
Name _____________________________________________________A16500: #REF!
Name _________________________________________________A16500: #REF!
Name ___________________________________________A16500: #REF!
Name __________________________________________arr3: {"Book1","4.09 FLORA DAN FAUNA.xls","4.22 PERLENGKAPAN SEKOLAH.xls"}
Name __________________________________________arr3: {"Book1","4.09 FLORA DAN FAUNA.xls","4.22 PERLENGKAPAN SEKOLAH.xls"}
Name __________________________________________mas1: {"Book1","4.09 FLORA DAN FAUNA.xls","4.22 PERLENGKAPAN SEKOLAH.xls"}
Name __________________________________________mas1: {"Book1","4.09 FLORA DAN FAUNA.xls","4.22 PERLENGKAPAN SEKOLAH.xls"}
Name __________________________________________mas12: {"Book1","4.09 FLORA DAN FAUNA.xls","4.22 PERLENGKAPAN SEKOLAH.xls"}
Name __________________________________________mas12: {"Book1","4.09 FLORA DAN FAUNA.xls","4.22 PERLENGKAPAN SEKOLAH.xls"}
Name __________________________________________mas4: {"Book1","4.09 FLORA DAN FAUNA.xls","4.22 PERLENGKAPAN SEKOLAH.xls"}
Name __________________________________________mas4: {"Book1","4.09 FLORA DAN FAUNA.xls","4.22 PERLENGKAPAN SEKOLAH.xls"}
Name __________________________________________mas5: {"Book1","4.09 FLORA DAN FAUNA.xls","4.22 PERLENGKAPAN SEKOLAH.xls"}
Name __________________________________________mas5: {"Book1","4.09 FLORA DAN FAUNA.xls","4.22 PERLENGKAPAN SEKOLAH.xls"}
Name __________________________________________mas6: {"Book1","4.09 FLORA DAN FAUNA.xls","4.22 PERLENGKAPAN SEKOLAH.xls"}
Name __________________________________________mas6: {"Book1","4.09 FLORA DAN FAUNA.xls","4.22 PERLENGKAPAN SEKOLAH.xls"}
Name __________________________________________mas7: {"Book1","4.09 FLORA DAN FAUNA.xls","4.22 PERLENGKAPAN SEKOLAH.xls"}
Name __________________________________________mas7: {"Book1","4.09 FLORA DAN FAUNA.xls","4.22 PERLENGKAPAN SEKOLAH.xls"}
Name __________________________________________mas8: {"Book1","4.09 FLORA DAN FAUNA.xls","4.22 PERLENGKAPAN SEKOLAH.xls"}
Name __________________________________________mas8: {"Book1","4.09 FLORA DAN FAUNA.xls","4.22 PERLENGKAPAN SEKOLAH.xls"}
Name __________________________________________mas9: {"Book1","4.09 FLORA DAN FAUNA.xls","4.22 PERLENGKAPAN SEKOLAH.xls"}
Name __________________________________________mas9: {"Book1","4.09 FLORA DAN FAUNA.xls","4.22 PERLENGKAPAN SEKOLAH.xls"}
Name __________________________________________me1: {"Book1","4.09 FLORA DAN FAUNA.xls","4.22 PERLENGKAPAN SEKOLAH.xls"}
Name __________________________________________me1: {"Book1","4.09 FLORA DAN FAUNA.xls","4.22 PERLENGKAPAN SEKOLAH.xls"}
Name __________________________________________me2: {"Book1","4.09 FLORA DAN FAUNA.xls","4.22 PERLENGKAPAN SEKOLAH.xls"}
Name __________________________________________me2: {"Book1","4.09 FLORA DAN FAUNA.xls","4.22 PERLENGKAPAN SEKOLAH.xls"}
Name __________________________________________me3: {"Book1","4.09 FLORA DAN FAUNA.xls","4.22 PERLENGKAPAN SEKOLAH.xls"}
Name __________________________________________me3: {"Book1","4.09 FLORA DAN FAUNA.xls","4.22 PERLENGKAPAN SEKOLAH.xls"}
Name __________________________________________me4: {"Book1","4.09 FLORA DAN FAUNA.xls","4.22 PERLENGKAPAN SEKOLAH.xls"}
Name __________________________________________me4: {"Book1","4.09 FLORA DAN FAUNA.xls","4.22 PERLENGKAPAN SEKOLAH.xls"}
Name __________________________________________me5: {"Book1","4.09 FLORA DAN FAUNA.xls","4.22 PERLENGKAPAN SEKOLAH.xls"}
Name __________________________________________me5: {"Book1","4.09 FLORA DAN FAUNA.xls","4.22 PERLENGKAPAN SEKOLAH.xls"}
Name __________________________________________mek3: {"Book1","4.09 FLORA DAN FAUNA.xls","4.22 PERLENGKAPAN SEKOLAH.xls"}
Name __________________________________________mek3: {"Book1","4.09 FLORA DAN FAUNA.xls","4.22 PERLENGKAPAN SEKOLAH.xls"}
Name __________________________________________mek5: {"Book1","4.09 FLORA DAN FAUNA.xls","4.22 PERLENGKAPAN SEKOLAH.xls"}
Name __________________________________________mek5: {"Book1","4.09 FLORA DAN FAUNA.xls","4.22 PERLENGKAPAN SEKOLAH.xls"}
Name _________________________________________arr3: {"Book1","4.09 FLORA DAN FAUNA.xls","4.22 PERLENGKAPAN SEKOLAH.xls"}

Sheet REKAP Tot
A2: REKAPITULASI RENCANA ANGGARAN BIAYA ( RAB )
A4: ='RAB GIK UGM'!A2 -> Pekerjaan | C4: ='RAB GIK UGM'!C2 -> : Pembangunan Gedung Gelanggang Inovasi dan Kreativitas (GIK) UGM Tahap II
A5: ='RAB GIK UGM'!A3 -> Lokasi | C5: ='RAB GIK UGM'!C3 -> : Jl. Pancasila No. 1, Blimbing Sari, Caturtunggal, Kec. Depok, Kabupaten Sleman, Daerah Istimewa Yogyakarta
A6: ='RAB GIK UGM'!A4 -> Sumber Dana | C6: ='RAB GIK UGM'!C4 -> : APBN
A7: ='RAB GIK UGM'!A5 -> Tahun Anggaran | C7: ='RAB GIK UGM'!C5 -> : Tahun Jamak (MYC) 2025 - 2026
A9: No. | C9: URAIAN PEKERJAAN | E9: JUMLAH HARGA
A10: 1 | C10: 2 | E10: 3
B11: A | C11: ='RAB GIK UGM'!C9 -> MATA PEMBAYARAN UMUM
C12: ='RAB GIK UGM'!C10 -> PEKERJAAN PERSIAPAN | E12: =SUM('RAB GIK UGM'!G11:G15) -> 3.1605755e+08
B13: B | C13: ='RAB GIK UGM'!C16 -> MATA PEMBAYARAN PERKIRAAN BIAYA PENERAPAN SMKKK | E13: =SUM('RAB GIK UGM'!G18:G86) -> 9.8203084e+08
A14: C | C14: ='RAB GIK UGM'!C87 -> MATA PEMBAYARAN PEKERJAAN UTAMA
C15: ='RAB GIK UGM'!C88 -> PEKERJAAN STRUKTUR | E15: =SUM('RAB GIK UGM'!G91:G139) -> 2.9049803e+09
C16: PEKERJAAN ARSITEKTUR | E16: =SUM('RAB GIK UGM'!G143:G245) -> 2.6502056e+10
C17: PEKERJAAN MEP | E17: =SUM('RAB GIK UGM'!G250:G1300) -> 1.1248593e+11
D19: JUMLAH | E19: =SUM(E12:E18) -> 1.4319106e+11 | F19: 196224783000
D20: PPN 11 % | E20: =E19*0.11 -> 1.5751016e+10
D21: JUMLAH TOTAL | E21: =SUM(E19:E20) -> 1.5894207e+11
D22: PEMBULATAN | E22: =INT(E21/10000)*10000 -> 158942070000 | F22: =E21/F19*100 -> 81 | G22: %
A23: Terbilang : | C23: =B48 -> Seratus Lima Puluh Delapan Milyar Sembilan Ratus Empat Puluh Dua Juta Tujuh Puluh Ribu Rupiah
D26: Semarang, 27 November 2025
D27: Penawar
D28: PT. SINAR CERAH SEMPURNA
D33: Ir H SOEHARTO, MT
D34: Direktur
B48: =PROPER(CONCATENATE("",IF(VALUE(B50)>0,CONCATENATE(C50,D50,"trilyun "),""),IF(VALUE(B51)>0,CONCATENATE(C51,D51,"milyar "),""),IF(VALUE(B52)>0,CONCATENATE(C52,D52,"juta "),""),IF(VALUE(B53)>0,CONCATENATE(C53,D53,"ribu "),""),C54,D54,IF(LEN(B55)>0,CONCATENATE(IF(B50+B51+B52+B53+B54=0,"nol koma ","koma "),C55),C55),IF(AND(LEN(B55)=0,B50+B51+B52+B53+B54=0),"","rupiah "))) -> Seratus Lima Puluh Delapan Milyar Sembilan Ratus Empat Puluh Dua Juta Tujuh Puluh Ribu Rupiah
B49: =E22 -> 158942070000
B50: =IF(LEN(RIGHT(INT(B49/1000000000000),3))<3,CONCATENATE(0,RIGHT(INT(B49/1000000000000),3)),RIGHT(INT(B49/1000000000000),3)) -> 00 | C50: =IF(LEN(VALUE(B50))=3,CONCATENATE(VLOOKUP(VALUE(LEFT(B50,1)),B56:C65,2),"ratus "),"") | D50: =IF(AND(VALUE(LEFT(RIGHT(B50,2),1))=1,VALUE(RIGHT(B50,1))>0),CONCATENATE(VLOOKUP(VALUE(RIGHT(B50,1)),B57:C65,2),"belas "),IF(VALUE(LEFT(RIGHT(B50,2),1))=0,VLOOKUP(VALUE(RIGHT(B50,1)),B56:D65,3),CONCATENATE(VLOOKUP(VALUE(LEFT(RIGHT(B50,2),1)),B57:C65,2),"puluh ",VLOOKUP(VALUE(RIGHT(B50,1)),B56:D65,3))))
B51: =IF(LEN(RIGHT(INT(B49/1000000000),3))<3,CONCATENATE(0,RIGHT(INT(B49/1000000000),3)),RIGHT(INT(B49/1000000000),3)) -> 158 | C51: =IF(LEN(VALUE(B51))=3,CONCATENATE(VLOOKUP(VALUE(LEFT(B51,1)),B56:C65,2),"ratus "),"") -> seratus | D51: =IF(AND(VALUE(LEFT(RIGHT(B51,2),1))=1,VALUE(RIGHT(B51,1))>0),CONCATENATE(VLOOKUP(VALUE(RIGHT(B51,1)),B57:C65,2),"belas "),IF(VALUE(LEFT(RIGHT(B51,2),1))=0,VLOOKUP(VALUE(RIGHT(B51,1)),B56:D65,3),CONCATENATE(VLOOKUP(VALUE(LEFT(RIGHT(B51,2),1)),B57:C65,2),"puluh ",VLOOKUP(VALUE(RIGHT(B51,1)),B56:D65,3)))) -> lima puluh delapan
B52: =IF(LEN(RIGHT(INT(B49/1000000),3))<3,CONCATENATE(0,RIGHT(INT(B49/1000000),3)),RIGHT(INT(B49/1000000),3)) -> 942 | C52: =IF(LEN(VALUE(B52))=3,CONCATENATE(VLOOKUP(VALUE(LEFT(B52,1)),B56:C65,2),"ratus "),"") -> sembilan ratus | D52: =IF(AND(VALUE(LEFT(RIGHT(B52,2),1))=1,VALUE(RIGHT(B52,1))>0),CONCATENATE(VLOOKUP(VALUE(RIGHT(B52,1)),B57:C65,2),"belas "),IF(VALUE(LEFT(RIGHT(B52,2),1))=0,VLOOKUP(VALUE(RIGHT(B52,1)),B56:D65,3),CONCATENATE(VLOOKUP(VALUE(LEFT(RIGHT(B52,2),1)),B57:C65,2),"puluh ",VLOOKUP(VALUE(RIGHT(B52,1)),B56:D65,3)))) -> empat puluh dua
B53: =IF(LEN(RIGHT(INT(B49/1000),3))<3,CONCATENATE(0,RIGHT(INT(B49/1000),3)),RIGHT(INT(B49/1000),3)) -> 070 | C53: =IF(LEN(VALUE(B53))=3,CONCATENATE(VLOOKUP(VALUE(LEFT(B53,1)),B56:C65,2),"ratus "),"") | D53: =IF(AND(VALUE(LEFT(RIGHT(B53,2),1))=1,VALUE(RIGHT(B53,1))>0),CONCATENATE(VLOOKUP(VALUE(RIGHT(B53,1)),B57:C65,2),"belas "),IF(VALUE(LEFT(RIGHT(B53,2),1))=0,VLOOKUP(VALUE(RIGHT(B53,1)),B56:D65,3),CONCATENATE(VLOOKUP(VALUE(LEFT(RIGHT(B53,2),1)),B57:C65,2),"puluh ",VLOOKUP(VALUE(RIGHT(B53,1)),B56:D65,3)))) -> tujuh puluh
B54: =IF(LEN(RIGHT(INT(B49),3))<3,CONCATENATE(0,RIGHT(INT(B49),3)),RIGHT(INT(B49),3)) -> 000 | C54: =IF(LEN(VALUE(B54))=3,CONCATENATE(VLOOKUP(VALUE(LEFT(B54,1)),B56:C65,2),"ratus "),"") | D54: =IF(AND(VALUE(LEFT(RIGHT(B54,2),1))=1,VALUE(RIGHT(B54,1))>0),CONCATENATE(VLOOKUP(VALUE(RIGHT(B54,1)),B57:C65,2),"belas "),IF(VALUE(LEFT(RIGHT(B54,2),1))=0,VLOOKUP(VALUE(RIGHT(B54,1)),B56:D65,3),CONCATENATE(VLOOKUP(VALUE(LEFT(RIGHT(B54,2),1)),B57:C65,2),"puluh ",VLOOKUP(VALUE(RIGHT(B54,1)),B56:D65,3))))
B55: =MID(ROUND((B49)-INT(B49),2),3,2) | C55: =IF(LEN(B55)=0,"",IF(AND(LEN(B55)=2,VALUE(LEFT(B55,1))=0),CONCATENATE("nol ",VLOOKUP(VALUE(RIGHT(B55,1)),B56:D65,3)),IF(LEN(B55)=1,VLOOKUP(VALUE(B55),B56:D65,3),IF(AND(LEN(B55)=2,VALUE(LEFT(B55,1))=1),CONCATENATE(VLOOKUP(VALUE(RIGHT(B55,1)),B56:C65,2),"belas "),CONCATENATE(VLOOKUP(VALUE(LEFT(B55,1)),B57:C65,2),"puluh ",VLOOKUP(VALUE(RIGHT(B55,1)),B57:D65,3))))))
B56: 0
B57: 1 | C57: se | D57: satu
B58: 2 | C58: dua | D58: dua
B59: 3 | C59: tiga | D59: tiga
B60: 4 | C60: empat | D60: empat
B61: 5 | C61: lima | D61: lima
B62: 6 | C62: enam | D62: enam
B63: 7 | C63: tujuh | D63: tujuh
...

Sheet SCHD
A2: TIME SCHEDULE / JADWAL WAKTU PELAKSANAAN
B3: ='RAB GIK UGM'!A2 -> Pekerjaan | E3: ='RAB GIK UGM'!C2 -> : Pembangunan Gedung Gelanggang Inovasi dan Kreativitas (GIK) UGM Tahap II
B4: ='RAB GIK UGM'!A3 -> Lokasi | E4: ='RAB GIK UGM'!C3 -> : Jl. Pancasila No. 1, Blimbing Sari, Caturtunggal, Kec. Depok, Kabupaten Sleman, Daerah Istimewa Yogyakarta
B5: ='RAB GIK UGM'!A4 -> Sumber Dana | E5: ='RAB GIK UGM'!C4 -> : APBN
B6: ='RAB GIK UGM'!A5 -> Tahun Anggaran | E6: ='RAB GIK UGM'!C5 -> : Tahun Jamak (MYC) 2025 - 2026
A8: NO | C8: URAIAN PEKERJAAN | H8: Nilai | I8: Waktu Pelaksanaan | BI8: PROSENTASE | BJ8: Ket
H9: Bobot | I9: Mg 1 | J9: Mg 2 | K9: Mg 3 | L9: Mg 4 | M9: Mg 5 | N9: Mg 6 | O9: Mg 7 | P9: Mg 8 | Q9: Mg 9 | R9: Mg 10 | S9: Mg 11 | T9: Mg 12 | U9: Mg 13 | V9: Mg 14 | W9: Mg 15 | X9: Mg 16 | Y9: Mg 17 | Z9: Mg 18 | AA9: Mg 19 | AB9: Mg 20 | AC9: Mg 21 | AD9: Mg 22 | AE9: Mg 23 | AF9: Mg 24 | AG9: Mg 25 | AH9: Mg 26 | AI9: Mg 27 | AJ9: Mg 28 | AK9: Mg 29 | AL9: Mg 30 | AM9: Mg 31 | AN9: Mg 32 | AO9: Mg 33 | AP9: Mg 34 | AQ9: Mg 35 | AR9: Mg 36 | AS9: Mg 37 | AT9: Mg 38 | AU9: Mg 39 | AV9: Mg 40 | AW9: Mg 41 | AX9: Mg 42 | AY9: Mg 43 | AZ9: Mg 44 | BA9: Mg 45 | BB9: Mg 46 | BC9: Mg 47 | BD9: Mg 48 | BE9: Mg 49 | BF9: Mg 50 | BG9: Mg 51 | BH9: Mg 52
H10: (%) | I10: 7 hr | J10: 7 hr | K10: 7 hr | L10: 7 hr | M10: 7 hr | N10: 7 hr | O10: 7 hr | P10: 7 hr | Q10: 7 hr | R10: 7 hr | S10: 7 hr | T10: 7 hr | U10: 7 hr | V10: 7 hr | W10: 7 hr | X10: 7 hr | Y10: 7 hr | Z10: 7 hr | AA10: 7 hr | AB10: 7 hr | AC10: 7 hr | AD10: 7 hr | AE10: 7 hr | AF10: 7 hr | AG10: 7 hr | AH10: 7 hr | AI10: 7 hr | AJ10: 7 hr | AK10: 7 hr | AL10: 7 hr | AM10: 7 hr | AN10: 7 hr | AO10: 7 hr | AP10: 7 hr | AQ10: 7 hr | AR10: 7 hr | AS10: 7 hr | AT10: 7 hr | AU10: 7 hr | AV10: 7 hr | AW10: 7 hr | AX10: 7 hr | AY10: 7 hr | AZ10: 7 hr | BA10: 7 hr | BB10: 7 hr | BC10: 7 hr | BD10: 7 hr | BE10: 7 hr | BF10: 7 hr | BG10: 7 hr | BH10: 3 hr
A11: 1 | C11: 2 | H11: 3 | I11: 4 | J11: 5 | K11: 6 | L11: 7 | M11: 8 | N11: 9 | O11: 10 | P11: 11 | Q11: 12 | R11: 13 | S11: 14 | T11: 15 | U11: 16 | V11: 17 | W11: 18 | X11: 19 | Y11: 20 | Z11: 21 | AA11: 22 | AB11: 23 | AC11: 24 | AD11: 25 | AE11: 26 | AF11: 27 | AG11: 28 | AH11: 29 | AI11: 30 | AJ11: 31 | AK11: 32 | AL11: 33 | AM11: 34 | AN11: 35 | AO11: 36 | AP11: 37 | AQ11: 38 | AR11: 39 | AS11: 40 | AT11: 41 | AU11: 42 | AV11: 43 | AW11: 44 | AX11: 45 | AY11: 46 | AZ11: 47 | BA11: 48 | BB11: 49 | BC11: 50 | BD11: 51 | BE11: 52 | BF11: 53 | BG11: 54 | BH11: 55 | BI11: 56 | BJ11: 57
BI12: 1 | BJ12: Jangka waktu pelaksanaan 360 (tiga ratus enam puluh ) hari kalender , Jangka waktu pemeliharaan 180 (seratus delapan puluh ) hari kalender
B13: ='RAB GIK UGM'!A9 -> A. | C13: ='RAB GIK UGM'!C9 -> MATA PEMBAYARAN UMUM | BL13: =SUM(I13:BH13)-H13 -> 0
C14: ='RAB GIK UGM'!C10 -> PEKERJAAN PERSIAPAN | G14: =SUM('RAB GIK UGM'!G11:G15) -> 3.1605755e+08 | H14: =G14/$G$75*100 -> 0.22072436 | I14: =H14/52 -> 0.0042446992 | J14: =I14 -> 0.0042446992 | K14: =J14 -> 0.0042446992 | L14: =K14 -> 0.0042446992 | M14: =L14 -> 0.0042446992 | N14: =M14 -> 0.0042446992 | O14: =N14 -> 0.0042446992 | P14: =O14 -> 0.0042446992 | Q14: =P14 -> 0.0042446992 | ... BH14: =BG14 -> 0.0042446992 | BL14: =SUM(I14:BH14)-H14 -> 0
B15: ='RAB GIK UGM'!A16 -> B. | C15: ='RAB GIK UGM'!C16 -> MATA PEMBAYARAN PERKIRAAN BIAYA PENERAPAN SMKKK | G15: =SUM('RAB GIK UGM'!G18:G86) -> 9.8203084e+08 | H15: =G15/$G$75*100 -> 0.68581855 | I15: =H15/52 -> 0.013188818 | J15: =I15 -> 0.013188818 | K15: =J15 -> 0.013188818 | L15: =K15 -> 0.013188818 | M15: =L15 -> 0.013188818 | N15: =M15 -> 0.013188818 | O15: =N15 -> 0.013188818 | P15: =O15 -> 0.013188818 | Q15: =P15 -> 0.013188818 | ... BH15: =BG15 -> 0.013188818 | BL15: =SUM(I15:BH15)-H15 -> 0
B16: ='RAB GIK UGM'!A87 -> C. | C16: ='RAB GIK UGM'!C87 -> MATA PEMBAYARAN PEKERJAAN UTAMA | H16: =G16/$G$75*100 -> 0 | BL16: =SUM(I16:BH16)-H16 -> 0
B17: ='RAB GIK UGM'!B88 -> I. | C17: ='RAB GIK UGM'!C88 -> PEKERJAAN STRUKTUR | H17: =G17/$G$75*100 -> 0 | BL17: =SUM(I17:BH17)-H17 -> 0
C18: ='RAB GIK UGM'!C90 -> RETAIL ROOF ZONA D | G18: =SUM('RAB GIK UGM'!G91:G102) -> 4.6433436e+08 | H18: =G18/$G$75*100 -> 0.32427609 | L18: =H18/3 -> 0.10809203 | M18: =L18 -> 0.10809203 | N18: =M18 -> 0.10809203 | BL18: =SUM(I18:BH18)-H18 -> 0
C19: ='RAB GIK UGM'!C103 -> RIGGING AUDITORIUM KECIL ZONA D | G19: =SUM('RAB GIK UGM'!G104:G107) -> 59111623 | H19: =G19/$G$75*100 -> 0.041281644 | M19: =H19/2 -> 0.020640822 | N19: =M19 -> 0.020640822 | BL19: =SUM(I19:BH19)-H19 -> 0
C20: ='RAB GIK UGM'!C108 -> ZONA F | H20: =G20/$G$75*100 -> 0 | BL20: =SUM(I20:BH20)-H20 -> 0
C21: ='RAB GIK UGM'!C109 -> AUDITORIUM BESAR ZONA F | G21: =SUM('RAB GIK UGM'!G111:G114) -> 2.2682657e+08 | H21: =G21/$G$75*100 -> 0.15840834 | O21: =H21/3 -> 0.052802779 | P21: =O21 -> 0.052802779 | Q21: =P21 -> 0.052802779 | BL21: =SUM(I21:BH21)-H21 -> 0
C22: ='RAB GIK UGM'!C115 -> Rigging Cyclorama, Forestage Bar I & II | G22: =SUM('RAB GIK UGM'!G116:G117) -> 32584685 | H22: =G22/$G$75*100 -> 0.022756089 | O22: =H22/3 -> 0.007585363 | P22: =O22 -> 0.007585363 | Q22: =P22 -> 0.007585363 | BL22: =SUM(I22:BH22)-H22 -> 0
C23: ='RAB GIK UGM'!C118 -> Side Bar Left & Right | G23: =SUM('RAB GIK UGM'!G119:G123) -> 1.5250822e+08 | H23: =G23/$G$75*100 -> 0.10650681 | Q23: =H23/3 -> 0.035502269 | R23: =Q23 -> 0.035502269 | S23: =R23 -> 0.035502269 | BL23: =SUM(I23:BH23)-H23 -> 0
C24: ='RAB GIK UGM'!C124 -> Rigging Main Curtain | G24: =SUM('RAB GIK UGM'!G125:G127) -> 2.5632249e+08 | H24: =G24/$G$75*100 -> 0.17900733 | R24: =H24/3 -> 0.05966911 | S24: =R24 -> 0.05966911 | T24: =S24 -> 0.05966911 | BL24: =SUM(I24:BH24)-H24 -> 0
C25: ='RAB GIK UGM'!C128 -> MEZZANINE RUANG FOH (Front of House) | G25: =SUM('RAB GIK UGM'!G129:G134) -> 2.1856374e+08 | H25: =G25/$G$75*100 -> 0.15263784 | R25: =H25/3 -> 0.05087928 | S25: =R25 -> 0.05087928 | T25: =S25 -> 0.05087928 | BL25: =SUM(I25:BH25)-H25 -> 0
C26: ='RAB GIK UGM'!C135 -> ZONA B | G26: =SUM('RAB GIK UGM'!G137:G139) -> 1.4947286e+09 | H26: =G26/$G$75*100 -> 1.0438701 | T26: =H26/3 -> 0.34795669 | U26: =T26 -> 0.34795669 | V26: =U26 -> 0.34795669 | BL26: =SUM(I26:BH26)-H26 -> 0
B27: ='RAB GIK UGM'!B140 -> II. | C27: ='RAB GIK UGM'!C140 -> PEKERJAAN ARSITEKTUR | H27: =G27/$G$75*100 -> 0 | BL27: =SUM(I27:BH27)-H27 -> 0
C28: ='RAB GIK UGM'!C141 -> 0. GENERAL | G28: =SUM('RAB GIK UGM'!G143:G144) -> 6.4367539e+08 | H28: =G28/$G$75*100 -> 0.44952206 | X28: =H28/6 -> 0.074920343 | Y28: =X28 -> 0.074920343 | Z28: =Y28 -> 0.074920343 | AA28: =Z28 -> 0.074920343 | AB28: =AA28 -> 0.074920343 | AC28: =AB28 -> 0.074920343 | BL28: =SUM(I28:BH28)-H28 -> 0
C29: ='RAB GIK UGM'!C145 -> TANGGA KEBAKARAN | G29: =SUM('RAB GIK UGM'!G147:G157) -> 1.1690487e+09 | H29: =G29/$G$75*100 -> 0.81642578 | N29: =H29/6 -> 0.13607096 | O29: =N29 -> 0.13607096 | P29: =O29 -> 0.13607096 | Q29: =P29 -> 0.13607096 | R29: =Q29 -> 0.13607096 | S29: =R29 -> 0.13607096 | BI29: 0.75 | BL29: =SUM(I29:BH29)-H29 -> 0
C30: TERITIS GRC dan LISTPLANK (ZONA EKS BOOKSTORE) | G30: =SUM('RAB GIK UGM'!G159:G160) -> 1.0403471e+09 | H30: =G30/$G$75*100 -> 0.72654474 | O30: =H30/6 -> 0.12109079 | P30: =O30 -> 0.12109079 | Q30: =P30 -> 0.12109079 | R30: =Q30 -> 0.12109079 | S30: =R30 -> 0.12109079 | T30: =S30 -> 0.12109079
C31: ='RAB GIK UGM'!C161 -> ZONA B | G31: =SUM('RAB GIK UGM'!G162:G164) -> 1.3929139e+09 | H31: =G31/$G$75*100 -> 0.97276598 | P31: =H31/6 -> 0.16212766 | Q31: =P31 -> 0.16212766 | R31: =Q31 -> 0.16212766 | S31: =R31 -> 0.16212766 | T31: =S31 -> 0.16212766 | U31: =T31 -> 0.16212766 | BL31: =SUM(I31:BH31)-H31 -> 0
C32: ='RAB GIK UGM'!C165 -> ZONA D | G32: =SUM('RAB GIK UGM'!G167:G178) -> 2.779894e+09 | H32: =G32/$G$75*100 -> 1.941388 | R32: =H32/6 -> 0.32356466 | S32: =R32 -> 0.32356466 | T32: =S32 -> 0.32356466 | U32: =T32 -> 0.32356466 | V32: =U32 -> 0.32356466 | W32: =V32 -> 0.32356466 | BL32: =SUM(I32:BH32)-H32 -> 0
C33: ='RAB GIK UGM'!C179 -> Kanopi Void Ramp Putar Zona D | G33: =SUM('RAB GIK UGM'!G180:G197) -> 4.5687137e+09 | H33: =G33/$G$75*100 -> 3.1906417 | T33: =H33/6 -> 0.53177362 | U33: =T33 -> 0.53177362 | V33: =U33 -> 0.53177362 | W33: =V33 -> 0.53177362 | X33: =W33 -> 0.53177362 | Y33: =X33 -> 0.53177362 | BL33: =SUM(I33:BH33)-H33 -> 0
C34: ='RAB GIK UGM'!C198 -> ZONA F | G34: =SUM('RAB GIK UGM'!G200:G217) -> 1.0464988e+10 | H34: =G34/$G$75*100 -> 7.3084087 | AD34: =H34/15 -> 0.48722725 | AE34: =AD34 -> 0.48722725 | AF34: =AE34 -> 0.48722725 | AG34: =AF34 -> 0.48722725 | AH34: =AG34 -> 0.48722725 | AI34: =AH34 -> 0.48722725 | AJ34: =AI34 -> 0.48722725 | AK34: =AJ34 -> 0.48722725 | AL34: =AK34 -> 0.48722725 | ... AR34: =AQ34 -> 0.48722725 | BL34: =SUM(I34:BH34)-H34 -> 0
C35: ='RAB GIK UGM'!$C$218 -> ZONA BNI | G35: =SUM('RAB GIK UGM'!G219:G222) -> 6.2415312e+08 | H35: =G35/$G$75*100 -> 0.43588834 | X35: =H35/6 -> 0.072648056 | Y35: =X35 -> 0.072648056 | Z35: =Y35 -> 0.072648056 | AA35: =Z35 -> 0.072648056 | AB35: =AA35 -> 0.072648056 | AC35: =AB35 -> 0.072648056 | BL35: =SUM(I35:BH35)-H35 -> 0
C36: ='RAB GIK UGM'!C223 -> TAMBAHAN BARU/ PRASARANA PENDUKUNG PENGELOLAAN | G36: =SUM('RAB GIK UGM'!G224:G243) -> 2.9443224e+09 | H36: =G36/$G$75*100 -> 2.0562194 | Z36: =H36/6 -> 0.34270324 | AA36: =Z36 -> 0.34270324 | AB36: =AA36 -> 0.34270324 | AC36: =AB36 -> 0.34270324 | AD36: =AC36 -> 0.34270324 | AE36: =AD36 -> 0.34270324 | BL36: =SUM(I36:BH36)-H36 -> 0
C37: ='RAB GIK UGM'!C244 -> ROOFTOP | G37: =SUM('RAB GIK UGM'!G245) -> 874000000 | H37: =G37/$G$75*100 -> 0.61037331 | AB37: =H37/6 -> 0.10172889 | AC37: =AB37 -> 0.10172889 | AD37: =AC37 -> 0.10172889 | AE37: =AD37 -> 0.10172889 | AF37: =AE37 -> 0.10172889 | AG37: =AF37 -> 0.10172889 | BL37: =SUM(I37:BH37)-H37 -> 0
B38: ='RAB GIK UGM'!B246 -> III. | C38: ='RAB GIK UGM'!C246 -> PEKERJAAN ELEKTRIKAL DAN ELEKTRONIKA | H38: =G38/$G$75*100 -> 0 | BL38: =SUM(I38:BH38)-H38 -> 0
C39: ='RAB GIK UGM'!C247 -> SUMBER DAYA DAN DISTRIBUSI | H39: =G39/$G$75*100 -> 0 | BL39: =SUM(I39:BH39)-H39 -> 0
C40: ='RAB GIK UGM'!C248 -> SUPPLY DAYA FAN | G40: =SUM('RAB GIK UGM'!G250:G266) -> 33578147 | H40: =G40/$G$75*100 -> 0.023449891 | AN40: =H40/5 -> 0.0046899782 | AO40: =AN40 -> 0.0046899782 | AP40: =AO40 -> 0.0046899782 | AQ40: =AP40 -> 0.0046899782 | AR40: =AQ40 -> 0.0046899782 | BL40: =SUM(I40:BH40)-H40 -> 0
C41: ='RAB GIK UGM'!C267 -> ACTIVE HARMONIC FILTER (AHF) | G41: =SUM('RAB GIK UGM'!G269:G282) -> 894113880 | H41: =G41/$G$75*100 -> 0.62442019 | AP41: =H41/5 -> 0.12488404 | AQ41: =AP41 -> 0.12488404 | AR41: =AQ41 -> 0.12488404 | AS41: =AR41 -> 0.12488404 | AT41: =AS41 -> 0.12488404 | BL41: =SUM(I41:BH41)-H41 -> 0
C42: ='RAB GIK UGM'!C283 -> INSTALASI GENSET | G42: =SUM('RAB GIK UGM'!G285:G344) -> 1.5362531e+10 | H42: =G42/$G$75*100 -> 10.728694 | AR42: =H42/10 -> 1.0728694 | AS42: =AR42 -> 1.0728694 | AT42: =AS42 -> 1.0728694 | AU42: =AT42 -> 1.0728694 | AV42: =AU42 -> 1.0728694 | AW42: =AV42 -> 1.0728694 | AX42: =AW42 -> 1.0728694 | AY42: =AX42 -> 1.0728694 | AZ42: =AY42 -> 1.0728694 | BA42: =AZ42 -> 1.0728694 | BL42: =SUM(I42:BH42)-H42 -> 0
...

Sheet SCHD (2)
A2: TIME SCHEDULE / JADWAL WAKTU PELAKSANAAN
B3: ='RAB GIK UGM'!A2 -> Pekerjaan | E3: ='RAB GIK UGM'!C2 -> : Pembangunan Gedung Gelanggang Inovasi dan Kreativitas (GIK) UGM Tahap II
B4: ='RAB GIK UGM'!A3 -> Lokasi | E4: ='RAB GIK UGM'!C3 -> : Jl. Pancasila No. 1, Blimbing Sari, Caturtunggal, Kec. Depok, Kabupaten Sleman, Daerah Istimewa Yogyakarta
B5: ='RAB GIK UGM'!A4 -> Sumber Dana | E5: ='RAB GIK UGM'!C4 -> : APBN
B6: ='RAB GIK UGM'!A5 -> Tahun Anggaran | E6: ='RAB GIK UGM'!C5 -> : Tahun Jamak (MYC) 2025 - 2026 | BG6: =51*7 -> 357
A8: NO | C8: URAIAN PEKERJAAN | H8: Nilai | I8: Waktu Pelaksanaan | BI8: PROSENTASE | BJ8: Ket
H9: Bobot | I9: Mg 1 | J9: Mg 2 | K9: Mg 3 | L9: Mg 4 | M9: Mg 5 | N9: Mg 6 | O9: Mg 7 | P9: Mg 8 | Q9: Mg 9 | R9: Mg 10 | S9: Mg 11 | T9: Mg 12 | U9: Mg 13 | V9: Mg 14 | W9: Mg 15 | X9: Mg 16 | Y9: Mg 17 | Z9: Mg 18 | AA9: Mg 19 | AB9: Mg 20 | AC9: Mg 21 | AD9: Mg 22 | AE9: Mg 23 | AF9: Mg 24 | AG9: Mg 25 | AH9: Mg 26 | AI9: Mg 27 | AJ9: Mg 28 | AK9: Mg 29 | AL9: Mg 30 | AM9: Mg 31 | AN9: Mg 32 | AO9: Mg 33 | AP9: Mg 34 | AQ9: Mg 35 | AR9: Mg 36 | AS9: Mg 37 | AT9: Mg 38 | AU9: Mg 39 | AV9: Mg 40 | AW9: Mg 41 | AX9: Mg 42 | AY9: Mg 43 | AZ9: Mg 44 | BA9: Mg 45 | BB9: Mg 46 | BC9: Mg 47 | BD9: Mg 48 | BE9: Mg 49 | BF9: Mg 50 | BG9: Mg 51 | BH9: Mg 52
H10: (%) | I10: 7 hr | J10: 7 hr | K10: 7 hr | L10: 7 hr | M10: 7 hr | N10: 7 hr | O10: 7 hr | P10: 7 hr | Q10: 7 hr | R10: 7 hr | S10: 7 hr | T10: 7 hr | U10: 7 hr | V10: 7 hr | W10: 7 hr | X10: 7 hr | Y10: 7 hr | Z10: 7 hr | AA10: 7 hr | AB10: 7 hr | AC10: 7 hr | AD10: 7 hr | AE10: 7 hr | AF10: 7 hr | AG10: 7 hr | AH10: 7 hr | AI10: 7 hr | AJ10: 7 hr | AK10: 7 hr | AL10: 7 hr | AM10: 7 hr | AN10: 7 hr | AO10: 7 hr | AP10: 7 hr | AQ10: 7 hr | AR10: 7 hr | AS10: 7 hr | AT10: 7 hr | AU10: 7 hr | AV10: 7 hr | AW10: 7 hr | AX10: 7 hr | AY10: 7 hr | AZ10: 7 hr | BA10: 7 hr | BB10: 7 hr | BC10: 7 hr | BD10: 7 hr | BE10: 7 hr | BF10: 7 hr | BG10: 7 hr | BH10: 3 hr
A11: 1 | C11: 2 | H11: 3 | I11: 4 | J11: 5 | K11: 6 | L11: 7 | M11: 8 | N11: 9 | O11: 10 | P11: 11 | Q11: 12 | R11: 13 | S11: 14 | T11: 15 | U11: 16 | V11: 17 | W11: 18 | X11: 19 | Y11: 20 | Z11: 21 | AA11: 22 | AB11: 23 | AC11: 24 | AD11: 25 | AE11: 26 | AF11: 27 | AG11: 28 | AH11: 29 | AI11: 30 | AJ11: 31 | AK11: 32 | AL11: 33 | AM11: 34 | AN11: 35 | AO11: 36 | AP11: 37 | AQ11: 38 | AR11: 39 | AS11: 40 | AT11: 41 | AU11: 42 | AV11: 43 | AW11: 44 | AX11: 45 | AY11: 46 | AZ11: 47 | BA11: 48 | BB11: 49 | BC11: 50 | BD11: 51 | BE11: 52 | BF11: 53 | BG11: 54 | BH11: 55 | BI11: 56 | BJ11: 57
BI12: 1 | BJ12: Jangka waktu pelaksanaan 360 (tiga ratus enam puluh ) hari kalender , Jangka waktu pemeliharaan 180 (seratus delapan puluh ) hari kalender
B13: ='RAB GIK UGM'!A9 -> A. | C13: ='RAB GIK UGM'!C9 -> MATA PEMBAYARAN UMUM | BL13: =SUM(I13:BH13)-H13 -> 0
C14: ='RAB GIK UGM'!C10 -> PEKERJAAN PERSIAPAN | G14: =SUM('RAB GIK UGM'!G11:G15) -> 3.1605755e+08 | H14: =G14/$G$75*100 -> 0.22072436 | I14: =H14/52 -> 0.0042446992 | J14: =I14 -> 0.0042446992 | K14: =J14 -> 0.0042446992 | L14: =K14 -> 0.0042446992 | M14: =L14 -> 0.0042446992 | N14: =M14 -> 0.0042446992 | O14: =N14 -> 0.0042446992 | P14: =O14 -> 0.0042446992 | Q14: =P14 -> 0.0042446992 | ... BH14: =BG14 -> 0.0042446992 | BL14: =SUM(I14:BH14)-H14 -> 0
B15: ='RAB GIK UGM'!A16 -> B. | C15: ='RAB GIK UGM'!C16 -> MATA PEMBAYARAN PERKIRAAN BIAYA PENERAPAN SMKKK | G15: =SUM('RAB GIK UGM'!G18:G86) -> 9.8203084e+08 | H15: =G15/$G$75*100 -> 0.68581855 | I15: =H15/52 -> 0.013188818 | J15: =I15 -> 0.013188818 | K15: =J15 -> 0.013188818 | L15: =K15 -> 0.013188818 | M15: =L15 -> 0.013188818 | N15: =M15 -> 0.013188818 | O15: =N15 -> 0.013188818 | P15: =O15 -> 0.013188818 | Q15: =P15 -> 0.013188818 | ... BH15: =BG15 -> 0.013188818 | BL15: =SUM(I15:BH15)-H15 -> 0
B16: ='RAB GIK UGM'!A87 -> C. | C16: ='RAB GIK UGM'!C87 -> MATA PEMBAYARAN PEKERJAAN UTAMA | H16: =G16/$G$75*100 -> 0 | BL16: =SUM(I16:BH16)-H16 -> 0
B17: ='RAB GIK UGM'!B88 -> I. | C17: ='RAB GIK UGM'!C88 -> PEKERJAAN STRUKTUR | H17: =G17/$G$75*100 -> 0 | BL17: =SUM(I17:BH17)-H17 -> 0
C18: ='RAB GIK UGM'!C90 -> RETAIL ROOF ZONA D | G18: =SUM('RAB GIK UGM'!G91:G102) -> 4.6433436e+08 | H18: =G18/$G$75*100 -> 0.32427609 | L18: =H18/3 -> 0.10809203 | M18: =L18 -> 0.10809203 | N18: =M18 -> 0.10809203 | BL18: =SUM(I18:BH18)-H18 -> 0
C19: ='RAB GIK UGM'!C103 -> RIGGING AUDITORIUM KECIL ZONA D | G19: =SUM('RAB GIK UGM'!G104:G107) -> 59111623 | H19: =G19/$G$75*100 -> 0.041281644 | M19: =H19/2 -> 0.020640822 | N19: =M19 -> 0.020640822 | BL19: =SUM(I19:BH19)-H19 -> 0
C20: ='RAB GIK UGM'!C108 -> ZONA F | H20: =G20/$G$75*100 -> 0 | BL20: =SUM(I20:BH20)-H20 -> 0
C21: ='RAB GIK UGM'!C109 -> AUDITORIUM BESAR ZONA F | G21: =SUM('RAB GIK UGM'!G111:G114) -> 2.2682657e+08 | H21: =G21/$G$75*100 -> 0.15840834 | O21: =H21/3 -> 0.052802779 | P21: =O21 -> 0.052802779 | Q21: =P21 -> 0.052802779 | BL21: =SUM(I21:BH21)-H21 -> 0
C22: ='RAB GIK UGM'!C115 -> Rigging Cyclorama, Forestage Bar I & II | G22: =SUM('RAB GIK UGM'!G116:G117) -> 32584685 | H22: =G22/$G$75*100 -> 0.022756089 | O22: =H22/3 -> 0.007585363 | P22: =O22 -> 0.007585363 | Q22: =P22 -> 0.007585363 | BL22: =SUM(I22:BH22)-H22 -> 0
C23: ='RAB GIK UGM'!C118 -> Side Bar Left & Right | G23: =SUM('RAB GIK UGM'!G119:G123) -> 1.5250822e+08 | H23: =G23/$G$75*100 -> 0.10650681 | Q23: =H23/3 -> 0.035502269 | R23: =Q23 -> 0.035502269 | S23: =R23 -> 0.035502269 | BL23: =SUM(I23:BH23)-H23 -> 0
C24: ='RAB GIK UGM'!C124 -> Rigging Main Curtain | G24: =SUM('RAB GIK UGM'!G125:G127) -> 2.5632249e+08 | H24: =G24/$G$75*100 -> 0.17900733 | R24: =H24/3 -> 0.05966911 | S24: =R24 -> 0.05966911 | T24: =S24 -> 0.05966911 | BL24: =SUM(I24:BH24)-H24 -> 0
C25: ='RAB GIK UGM'!C128 -> MEZZANINE RUANG FOH (Front of House) | G25: =SUM('RAB GIK UGM'!G129:G134) -> 2.1856374e+08 | H25: =G25/$G$75*100 -> 0.15263784 | R25: =H25/3 -> 0.05087928 | S25: =R25 -> 0.05087928 | T25: =S25 -> 0.05087928 | BL25: =SUM(I25:BH25)-H25 -> 0
C26: ='RAB GIK UGM'!C135 -> ZONA B | G26: =SUM('RAB GIK UGM'!G137:G139) -> 1.4947286e+09 | H26: =G26/$G$75*100 -> 1.0438701 | T26: =H26/3 -> 0.34795669 | U26: =T26 -> 0.34795669 | V26: =U26 -> 0.34795669 | BL26: =SUM(I26:BH26)-H26 -> 0
B27: ='RAB GIK UGM'!B140 -> II. | C27: ='RAB GIK UGM'!C140 -> PEKERJAAN ARSITEKTUR | H27: =G27/$G$75*100 -> 0 | BL27: =SUM(I27:BH27)-H27 -> 0
C28: ='RAB GIK UGM'!C141 -> 0. GENERAL | G28: =SUM('RAB GIK UGM'!G143:G144) -> 6.4367539e+08 | H28: =G28/$G$75*100 -> 0.44952206 | X28: =H28/6 -> 0.074920343 | Y28: =X28 -> 0.074920343 | Z28: =Y28 -> 0.074920343 | AA28: =Z28 -> 0.074920343 | AB28: =AA28 -> 0.074920343 | AC28: =AB28 -> 0.074920343 | BL28: =SUM(I28:BH28)-H28 -> 0
C29: ='RAB GIK UGM'!C145 -> TANGGA KEBAKARAN | G29: =SUM('RAB GIK UGM'!G147:G157) -> 1.1690487e+09 | H29: =G29/$G$75*100 -> 0.81642578 | N29: =H29/6 -> 0.13607096 | O29: =N29 -> 0.13607096 | P29: =O29 -> 0.13607096 | Q29: =P29 -> 0.13607096 | R29: =Q29 -> 0.13607096 | S29: =R29 -> 0.13607096 | BI29: 0.75 | BL29: =SUM(I29:BH29)-H29 -> 0
C30: TERITIS GRC dan LISTPLANK (ZONA EKS BOOKSTORE) | G30: =SUM('RAB GIK UGM'!G159:G160) -> 1.0403471e+09 | H30: =G30/$G$75*100 -> 0.72654474 | O30: =H30/6 -> 0.12109079 | P30: =O30 -> 0.12109079 | Q30: =P30 -> 0.12109079 | R30: =Q30 -> 0.12109079 | S30: =R30 -> 0.12109079 | T30: =S30 -> 0.12109079
C31: ='RAB GIK UGM'!C161 -> ZONA B | G31: =SUM('RAB GIK UGM'!G162:G164) -> 1.3929139e+09 | H31: =G31/$G$75*100 -> 0.97276598 | P31: =H31/6 -> 0.16212766 | Q31: =P31 -> 0.16212766 | R31: =Q31 -> 0.16212766 | S31: =R31 -> 0.16212766 | T31: =S31 -> 0.16212766 | U31: =T31 -> 0.16212766 | BL31: =SUM(I31:BH31)-H31 -> 0
C32: ='RAB GIK UGM'!C165 -> ZONA D | G32: =SUM('RAB GIK UGM'!G167:G178) -> 2.779894e+09 | H32: =G32/$G$75*100 -> 1.941388 | R32: =H32/6 -> 0.32356466 | S32: =R32 -> 0.32356466 | T32: =S32 -> 0.32356466 | U32: =T32 -> 0.32356466 | V32: =U32 -> 0.32356466 | W32: =V32 -> 0.32356466 | BL32: =SUM(I32:BH32)-H32 -> 0
C33: ='RAB GIK UGM'!C179 -> Kanopi Void Ramp Putar Zona D | G33: =SUM('RAB GIK UGM'!G180:G197) -> 4.5687137e+09 | H33: =G33/$G$75*100 -> 3.1906417 | T33: =H33/6 -> 0.53177362 | U33: =T33 -> 0.53177362 | V33: =U33 -> 0.53177362 | W33: =V33 -> 0.53177362 | X33: =W33 -> 0.53177362 | Y33: =X33 -> 0.53177362 | BL33: =SUM(I33:BH33)-H33 -> 0
C34: ='RAB GIK UGM'!C198 -> ZONA F | G34: =SUM('RAB GIK UGM'!G200:G217) -> 1.0464988e+10 | H34: =G34/$G$75*100 -> 7.3084087 | AD34: =H34/15 -> 0.48722725 | AE34: =AD34 -> 0.48722725 | AF34: =AE34 -> 0.48722725 | AG34: =AF34 -> 0.48722725 | AH34: =AG34 -> 0.48722725 | AI34: =AH34 -> 0.48722725 | AJ34: =AI34 -> 0.48722725 | AK34: =AJ34 -> 0.48722725 | AL34: =AK34 -> 0.48722725 | ... AR34: =AQ34 -> 0.48722725 | BL34: =SUM(I34:BH34)-H34 -> 0
C35: ='RAB GIK UGM'!$C$218 -> ZONA BNI | G35: =SUM('RAB GIK UGM'!G219:G222) -> 6.2415312e+08 | H35: =G35/$G$75*100 -> 0.43588834 | X35: =H35/6 -> 0.072648056 | Y35: =X35 -> 0.072648056 | Z35: =Y35 -> 0.072648056 | AA35: =Z35 -> 0.072648056 | AB35: =AA35 -> 0.072648056 | AC35: =AB35 -> 0.072648056 | BL35: =SUM(I35:BH35)-H35 -> 0
C36: ='RAB GIK UGM'!C223 -> TAMBAHAN BARU/ PRASARANA PENDUKUNG PENGELOLAAN | G36: =SUM('RAB GIK UGM'!G224:G243) -> 2.9443224e+09 | H36: =G36/$G$75*100 -> 2.0562194 | Z36: =H36/6 -> 0.34270324 | AA36: =Z36 -> 0.34270324 | AB36: =AA36 -> 0.34270324 | AC36: =AB36 -> 0.34270324 | AD36: =AC36 -> 0.34270324 | AE36: =AD36 -> 0.34270324 | BL36: =SUM(I36:BH36)-H36 -> 0
C37: ='RAB GIK UGM'!C244 -> ROOFTOP | G37: =SUM('RAB GIK UGM'!G245) -> 874000000 | H37: =G37/$G$75*100 -> 0.61037331 | AB37: =H37/6 -> 0.10172889 | AC37: =AB37 -> 0.10172889 | AD37: =AC37 -> 0.10172889 | AE37: =AD37 -> 0.10172889 | AF37: =AE37 -> 0.10172889 | AG37: =AF37 -> 0.10172889 | BL37: =SUM(I37:BH37)-H37 -> 0
B38: ='RAB GIK UGM'!B246 -> III. | C38: ='RAB GIK UGM'!C246 -> PEKERJAAN ELEKTRIKAL DAN ELEKTRONIKA | H38: =G38/$G$75*100 -> 0 | BL38: =SUM(I38:BH38)-H38 -> 0
C39: ='RAB GIK UGM'!C247 -> SUMBER DAYA DAN DISTRIBUSI | H39: =G39/$G$75*100 -> 0 | BL39: =SUM(I39:BH39)-H39 -> 0
C40: ='RAB GIK UGM'!C248 -> SUPPLY DAYA FAN | G40: =SUM('RAB GIK UGM'!G250:G266) -> 33578147 | H40: =G40/$G$75*100 -> 0.023449891 | AN40: =H40/5 -> 0.0046899782 | AO40: =AN40 -> 0.0046899782 | AP40: =AO40 -> 0.0046899782 | AQ40: =AP40 -> 0.0046899782 | AR40: =AQ40 -> 0.0046899782 | BL40: =SUM(I40:BH40)-H40 -> 0
C41: ='RAB GIK UGM'!C267 -> ACTIVE HARMONIC FILTER (AHF) | G41: =SUM('RAB GIK UGM'!G269:G282) -> 894113880 | H41: =G41/$G$75*100 -> 0.62442019 | AP41: =H41/5 -> 0.12488404 | AQ41: =AP41 -> 0.12488404 | AR41: =AQ41 -> 0.12488404 | AS41: =AR41 -> 0.12488404 | AT41: =AS41 -> 0.12488404 | BL41: =SUM(I41:BH41)-H41 -> 0
C42: ='RAB GIK UGM'!C283 -> INSTALASI GENSET | G42: =SUM('RAB GIK UGM'!G285:G344) -> 1.5362531e+10 | H42: =G42/$G$75*100 -> 10.728694 | J42: =H42/5 -> 2.1457389 | K42: =J42 -> 2.1457389 | AR42: =(H42-SUM(J42:K42))/10 -> 0.64372166 | AS42: =AR42 -> 0.64372166 | AT42: =AS42 -> 0.64372166 | AU42: =AT42 -> 0.64372166 | AV42: =AU42 -> 0.64372166 | AW42: =AV42 -> 0.64372166 | AX42: =AW42 -> 0.64372166 | AY42: =AX42 -> 0.64372166 | AZ42: =AY42 -> 0.64372166 | BA42: =AZ42 -> 0.64372166 | BL42: =SUM(I42:BH42)-H42 -> 0
...

Sheet RAB GIK UGM
A2: Pekerjaan | C2: : Pembangunan Gedung Gelanggang Inovasi dan Kreativitas (GIK) UGM Tahap II
A3: Lokasi | C3: : Jl. Pancasila No. 1, Blimbing Sari, Caturtunggal, Kec. Depok, Kabupaten Sleman, Daerah Istimewa Yogyakarta
A4: Sumber Dana | C4: : APBN
A5: Tahun Anggaran | C5: : Tahun Jamak (MYC) 2025 - 2026
A7: Nomor | C7: Jenis Barang/Jasa | D7: Satuan Unit | E7: Volume | F7: Harga Satuan (Rp) | G7: Jumlah Harga Satuan (Rp)
A8: 1 | C8: 2 | D8: 3 | E8: 4 | F8: 5 | G8: 6
A9: A. | C9: MATA PEMBAYARAN UMUM
C10: PEKERJAAN PERSIAPAN
C11: Pengukuran dan pemasangan Bouwplank | D11: m1 | E11: 120 | F11: ='Hrg Sat'!$G$10 -> 62700 | G11: =E11*F11 -> 7524000
C12: Papan nama proyek | D12: unit | E12: 1 | F12: 1750000 | G12: =E12*F12 -> 1750000
C13: Pembuatan gudang (sewa) | D13: m2 | E13: 80 | F13: ='Hrg Sat'!$G$13 -> 1587657 | G13: =E13*F13 -> 127012560
C14: Pembuatan bedeng pekerja (sewa) | D14: m2 | E14: 60 | F14: ='Hrg Sat'!$G$13 -> 1587657 | G14: =E14*F14 -> 95259420
C15: Sekat/Pagar Pembatas (Sewa) | D15: m1 | E15: 256.47 | F15: ='Hrg Sat'!$G$9 -> 329518.33 | G15: =E15*F15 -> 84511567
A16: B. | C16: MATA PEMBAYARAN PERKIRAAN BIAYA PENERAPAN SMKKK
C17: Penyiapan RKK
C18: Pembuatan dokumen RKK, RKPPL, RMLLP, RMPK | D18: set | E18: 1 | F18: 1450000 | G18: =E18*F18 -> 1450000
C19: Pembuatan prosedur dan instruksi kerja | D19: set | E19: 1 | F19: 750000 | G19: =E19*F19 -> 750000
C20: Penyusunan pelaporan penerapan SMKK | D20: set | E20: 1 | F20: 750000 | G20: =E20*F20 -> 750000
C21: Sosialisasi, promosi dan pelatihan
C22: Induksi Keselamatan Konstruksi (Safety Induction) | D22: org | E22: 100 | F22: 7500 | G22: =E22*F22 -> 750000
C23: Pengarahan Keselamatan Konstruksi (Safety Briefing) | D23: org | E23: 100 | F23: 7500 | G23: =E23*F23 -> 750000
C24: Pertemuan keselamatan (Safety Talk dan/atau Tool Box Meeting) | D24: org | E24: 100 | F24: 7500 | G24: =E24*F24 -> 750000
C25: Pelatihan Keselamatan Konstruksi
C26: Penggunaan bahan kimia (MSDS) | D26: org | E26: 25 | F26: 7500 | G26: =E26*F26 -> 187500
C27: Analisis keselamatan pekerjaan | D27: org | E27: 25 | F27: 7500 | G27: =E27*F27 -> 187500
C28: Perilaku berbasis keselamatan (Budaya Berkeselamatan konstruksi) | D28: org | E28: 25 | F28: 7500 | G28: =E28*F28 -> 187500
C29: P3K | D29: org | E29: 25 | F29: 7500 | G29: =E29*F29 -> 187500
C30: Simulasi Keselamatan Konstruksi | D30: org | E30: 50 | F30: 7500 | G30: =E30*F30 -> 375000
C31: Spanduk (Banner) | D31: lb | E31: 8 | F31: 450000 | G31: =E31*F31 -> 3600000
C32: Poster/leaflet | D32: lb | E32: 8 | F32: 175000 | G32: =E32*F32 -> 1400000
C33: Papan Informasi Keselamatan Konstruksi | D33: bh | E33: 10 | F33: 400000 | G33: =E33*F33 -> 4000000
C34: Alat Pelindung Kerja dan Alat Pelindung Diri
C35: APK antara lain
C36: Tali Keselamatan (Life Line) | D36: m | E36: 413.08 | F36: 25000 | G36: =E36*F36 -> 10327000
C37: Pagar Pengaman (Guard Railling) | D37: unit | E37: 95 | F37: 240000 | G37: =E37*F37 -> 22800000
C38: Pembatas Area (Restricted Area) | D38: roll | E38: 100 | F38: 250000 | G38: =E38*F38 -> 25000000
C39: APD antara lain
C40: Topi Pelindung (Safety Helmet) | D40: bh | E40: 300 | F40: 65000 | G40: =E40*F40 -> 19500000
C41: Pelindung Mata (Goggles, Spectacles) | D41: bh | E41: 250 | F41: 90000 | G41: =E41*F41 -> 22500000
C42: Pelindung telinga (ear plug, Ear Muff) | D42: psg | E42: 50 | F42: 10000 | G42: =E42*F42 -> 500000
...

Sheet Sheet3
I3: 1. CH-21 (AUDITORIUM CHAIR)
A4: 2. Genset kap. 2500 Kva prime tipe Silent (built up) | I4: 11. CH-20 (CLASS CHAIR D=800x550mm)
A5: 3. TV Interactive IFPD V6 TRANSCEND 86 INCH + WINDOWS I5 OPS | I5: 50. CH-11 (CHAIR)
A6: 4. AC Presisi-Data Center 18HP lengkap dengan: | I6: 69. CH-03 (LOUNGE CHAIR TIPE 2)
B7: AC Presisi Unit Indoor dan Outdoor (include media pre | I7: 70. CH-03 (LOUNGE CHAIR TIPE 1)
B8: filter+housing (bulitin) | I8: 81. CH-12 (CHAIR)
B9: Control sequence | I9: 82. CH-01 (WORKING CHAIR)
B10: Include: pemasangan,test partial (bektest, Flushing N2, Vacum, | I10: 83. CH-21 (EXTRA CLASS CHAIR (LEFT-HANDED) D=800x550mm))
B11: dll), mobilisasi dan demobilisasi | I11: 86. CH-10 (CHAIR)
B12: Dudukan Indoor AC | I12: 88. CH-07 (CHAIR)
B13: Dudukan outdoor AC | I13: 91. CH-05 (CHAIR)
B14: Freon R 410 A 18 Hp | I14: 93. CH-09 (LECTURER CHAIR)
B15: Drain pan 18 HP + Isolasi THK 8mm | I15: 94. CH-13 (CHAIR)
A16: 5. Stasiun pengisian kendaraan listrik umum (SPKLU) Mobil 60 KW | I16: 97. CH-09 (WORKING CHAIR)
A17: 6. Modular UPS N+1 (250 kVA) | I17: 100. CH-01 (ARM CHAIR)
A18: 7. Videotron Auditorium Besar | I18: 101. CH-02 (ARM CHAIR)
A19: 8. Server VM 32 Core | I19: 106. CH-04b (CHAIR TIPE 2)
A20: 9. Lift TKDN Kapasitas 1350 kg 2 Lantai | I20: 109. CH-04 (CHAIR TIPE 1)
A21: 10. Server Storage 24 Tera : QNAP TS-1273AU-RP-8G + 2 TB x 12 | I21: 115. CH-06 (CHAIR)
I22: 116. CH-14 (BAR CHAIR)
A23: 12. 80LT 300bar Cylinder Valve Assembly | I23: 118. CH-09 (CHAIR)
A24: 13. Videotron Auditorium Kecil | I24: 119. CH-01 (LECTURER CHAIR
A25: 14. C9300L-24T-4X-A Catalyst 9300L 24 P data, Network Essentials, | I25: 88. CH-07 (CHAIR)
A26: 4x10G Uplink
A27: 15. LED Downlight I-Series 20,5W 3000K
A28: 16. Speaker Line Array 3way 16 Ohm | I28: 59. CB-03 (CABINET 2800x500x1600mm)
A29: 17. Panel Active Harmonic Filter 380V 250A, lengkap dengan: | I29: 71. SB-01 (SOFA BED 2000x700mm)
A30: Active Harmonic Filter 150A | I30: 75. TB-11 (TABLE D=1400x750mm)
A31: Active Harmonic Filter 100A | I31: 102. TB-13 (TABLE D=800x750mm)
A32: Panel Circuit Breaker and Panel for AHF (inc asesories) 1 Unit | I32: 103. LA-01 (FlOOR LAMP)
A33: Dimensi : 2100 x 800 x 1000 mm | I33: 104. TB-08 (TABLE D=600x450mm)
A34: MCCB NSX 200A 3P 36KA | I34: 105. TB-15 (LECTURER TABLE D=1400x700mm)
A35: MCCB NSX 125A 3P 36KA
A36: Current Transformer : 400Hz Class 1 Clamp On (3xPhase) | I36: 107. TB-12 (TABLE D=1200x600x1100mm)
A37: 18. Videotron Sport Hall | I37: 108. SB-04 (SOFA BED 600x700x800mm)
A38: 19. Data Node Server Big Data
A39: 20. SFP+ 10G | I39: 110. BAR-02 (BAR TABLE 4000+3000x600x900mm)
A40: 21. Lampu LED 24500 lumen 5000K 245W | I40: 111. TB-15 (TABLE 1200x600x750mm)
A41: 22. LED Spot Track Light | I41: 112. TB-03 (TABLE D=800x750mm)
A42: 23. Kursi sport hall | I42: 113. TB-13 (Mimbar)
...

Sheet Hrg Sat
A1: DAFTAR HARGA SATUAN PEKERJAAN
A2: =Analisa!A3 -> TAHUN 2025
A5: No | B5: KODE | E5: Uraian | G5: Harga Satuan
A7: =Analisa!A11 | B7: =Analisa!B10 -> A.2.2.1 | C7: =Analisa!A10 -> A | E7: =Analisa!D10 -> HARGA SATUAN PEKERJAAN PERSIAPAN
A8: =Analisa!A12 -> 1 | B8: =Analisa!B12 -> A.2.2.1.2 | D8: =Analisa!C12 -> a | E8: =Analisa!D12 -> Pembuatan 1 m' pagar sementara dari seng gelombang tinggi 2 m' | F8: Rp. | G8: =Analisa!N31 -> 395422
B9: =Analisa!B33 -> A.2.2.1.2a | D9: =Analisa!C33 -> b | E9: =Analisa!D33 -> Pembuatan 1 m' pagar sementara dari seng gelombang tinggi 2 m' (sewa) | F9: Rp. | G9: =Analisa!N34 -> 329518.33
A10: =Analisa!A37 -> 2 | B10: =Analisa!B37 -> A.2.2.1.4 | E10: =Analisa!D37 -> Pengukuran dan pemasangan 1 m' Bouwplank | F10: Rp. | G10: =Analisa!N52 -> 62700
A11: =Analisa!A56 -> 3 | B11: =Analisa!B56 -> A.2.2.1.9 | E11: =Analisa!D56 -> Pembersihan 1 m2 lapangan dan perataan | F11: Rp. | G11: =Analisa!N64 -> 22000
A12: =Analisa!A66 -> 4 | B12: =Analisa!B66 -> A.2.2.1.14 | E12: =Analisa!D66 -> Pembongkaran 1 m3 dinding tembok bata | F12: Rp. | G12: =Analisa!N74 -> 971657
A13: =Analisa!A98 -> 0 | B13: =Analisa!B98 -> 0 | E13: =Analisa!D76 -> 1 m2 Kantor sementara/ Rumah jaga/ Gudang semen dan peralatan lantai plesteran, dinding setengah tembok (sewa) | F13: Rp. | G13: =Analisa!N102 -> 1587657
A14: =Analisa!A105 -> 6 | B14: =Analisa!B105 -> Dihit.2 | E14: =Analisa!D105 -> Listrik kerja per bulan ( kebutuhan bahan bakar genset ) | F14: Rp. | G14: =Analisa!N111 -> 5346000
A15: =Analisa!A113 -> 7 | B15: =Analisa!B113 -> Dihit.3 | E15: =Analisa!D113 -> Biaya sewa 1 unit tower crane selama 8 bulan | F15: Rp. | G15: =Analisa!N125 -> 1.407649e+09
A16: =Analisa!A127 -> 8 | B16: =Analisa!B127 -> Dihit.4 | E16: =Analisa!D127 -> Biaya sewa 1 unit hoist lift/ lift barang selama 4 bulan | F16: Rp. | G16: =Analisa!N137 -> 105125000
B17: =Analisa!B139 -> A.2.3.1 | C17: =Analisa!A139 -> B | E17: =Analisa!D139 -> HARGA SATUAN PEKERJAAN TANAH
A18: =Analisa!A141 -> 9 | B18: =Analisa!B141 -> A.2.3.1.1 | E18: =Analisa!D141 -> Penggalian 1 m3 tanah biasa sedalam 1 m | F18: Rp. | G18: =Analisa!N149 -> 53625
A19: =Analisa!A151 -> 10 | B19: =Analisa!B151 -> A.2.3.1.2 | E19: =Analisa!D151 -> Penggalian 1 m3 tanah biasa sedalam 2 m | F19: Rp. | G19: =Analisa!N162 -> 395175
A20: =Analisa!A164 -> 11 | B20: =Analisa!B164 -> A.2.3.1.3 | E20: =Analisa!D164 -> Penggalian 1 m3 tanah biasa sedalam 3 m | F20: Rp. | G20: =Analisa!N174 -> 419430
A21: =Analisa!A176 -> 12 | B21: =Analisa!B176 -> A.2.3.1.9 | E21: =Analisa!D176 -> Pengurugan kembali 1 m3 Pengurugan kembali 1 m3 galian tanah | F21: Rp. | G21: =ROUNDDOWN(G18/2,0) -> 26812
A22: =Analisa!A180 -> 13 | B22: =Analisa!B180 -> A.2.3.1.11 | E22: =Analisa!D180 -> Pengurugan 1 m3 dengan Pasir urug | F22: Rp. | G22: =Analisa!N191 -> 293700
A23: =Analisa!A193 -> 14 | B23: =Analisa!B193 -> A.2.3.1.14 | E23: =Analisa!D193 -> Mengurug sirtu padat | F23: Rp. | G23: =Analisa!N204 -> 289300
A24: =Analisa!A206 -> 15 | B24: =Analisa!B206 -> A.2.3.1.14a | E24: =Analisa!D206 -> Pengurugan 1 m3 Tanah | F24: Rp. | G24: =Analisa!N217 -> 97900
A25: =Analisa!A219 -> 16 | B25: =Analisa!B219 -> Dihit.5 | E25: =Analisa!D219 -> Mengurug tanah dan pemadatan alat sederhana per m3 | F25: Rp. | G25: =Analisa!N233 -> 81708
A26: =Analisa!A235 -> 17 | B26: =Analisa!B235 -> Dihit.6 | E26: =Analisa!D235 -> Mengurug tanah ( tanah existing ) dan pemadatan alat sederhana per m3 | F26: Rp. | G26: =Analisa!N245 -> 47883
A27: =Analisa!A247 -> 18 | B27: =Analisa!B247 -> A.2.3.1.17a | E27: =Analisa!D247 -> Pengurugan 1 M3 tanah urug (mendatangkan) dan dipadatkan ( alat mekanis ) | F27: Rp. | G27: =Analisa!N266 -> 265355
A28: =Analisa!A268 -> 19 | B28: =Analisa!B268 -> A.2.3.1.17b | E28: =Analisa!D268 -> Pengurugan 1 M3 tanah urug (menggunakan tanah existing) dan dipadatkan ( alat mekanis ) | F28: Rp. | G28: =Analisa!N287 -> 205955
A29: =Analisa!A289 -> 20 | B29: =Analisa!B289 -> A.2.3.1.8 | E29: =Analisa!D289 -> 1 m3 MembuangTanah sejauh 30 m' | F29: Rp. | G29: =Analisa!N297 -> 47025
A30: =Analisa!A299 -> 21 | B30: =Analisa!B299 -> A.2.3.1.10 | E30: =Analisa!D299 -> 1 m3 Pemadatan Tanah (per 20 cm) | F30: Rp. | G30: =Analisa!N307 -> 77000
A31: =Analisa!A309 -> 22 | B31: =Analisa!B309 -> Dihit.7 | E31: =Analisa!D309 -> 1 m3 Galian tanah keras dibuang di sekitar lokasi pekerjaan (mekanis) | F31: Rp. | G31: =Analisa!N321 -> 9043
A32: =Analisa!A323 -> 23 | B32: =Analisa!B323 -> Dihit.8 | E32: =Analisa!D323 -> 1 m3 Tanah di hamparkan, diratakan, di rapihkan dan di padatkan ( alat mekanis ) | F32: Rp. | G32: =Analisa!N336 -> 29070
A33: =Analisa!A338 -> 24 | B33: =Analisa!B338 -> Dihit.9 | E33: =Analisa!D338 -> 1 m3 Tanah di angkut sejauh 5 km | F33: Rp. | G33: =Analisa!N357 -> 32450
A34: =Analisa!A359 -> 25 | B34: =Analisa!B359 -> Dihit. | E34: =Analisa!D359 -> 1 m2 Pembongkaran dinding eksisting | F34: Rp. | G34: =Analisa!N370 -> 119542
B35: =Analisa!B375 -> A.3.2.1 | C35: =Analisa!A375 -> C | E35: =Analisa!D375 -> HARGA SATUAN PEKERJAAN PONDASI
A36: =Analisa!A377 -> 26 | B36: =Analisa!B377 -> A.3.2.1.3 | E36: =Analisa!D377 -> Pemasangan 1 m3 pondasi batu belah campuran 1SP : 5PP | F36: Rp. | G36: =Analisa!N392 -> 770437
A37: =Analisa!A394 -> 27 | B37: =Analisa!B394 -> A.3.2.1.9 | E37: =Analisa!D394 -> Pemasangan 1 m3 batu kosong (anstamping) | F37: Rp. | G37: =Analisa!N408 -> 551908
B38: =Analisa!B410 -> A.4.1.1 | C38: =Analisa!A410 -> D | E38: =Analisa!D410 -> SATUAN PEKERJAAN BETON
A39: =Analisa!A412 -> 28 | B39: =Analisa!B412 -> A.4.1.1.4 | E39: =Analisa!D412 -> Membuat 1 m3 lantai kerja beton mutu f'c = 7,4 MPa (K 100) slump (3-6) cm w/c = 0,87 | F39: Rp. | G39: =Analisa!N428 -> 935322
A40: =Analisa!A430 -> 29 | B40: =Analisa!B430 -> A.4.1.1.5 | E40: =Analisa!D430 -> Membuat 1 m3 beton mutu f'c = 14,5 MPa (K 175) slump (12± 2) cm w/c = 0,66 | F40: Rp. | G40: =Analisa!N446 -> 1121968
A41: =Analisa!A448 -> 30 | B41: =Analisa!B448 -> A.4.1.1.8 | E41: =Analisa!D448 -> Membuat 1 m3 beton mutu f'c = 21,7 MPa (K 250) slump (12±2) cm w/c = 0,56 | F41: Rp. | G41: =Analisa!N464 -> 1191360
A42: =Analisa!A466 -> 31 | B42: =Analisa!B466 -> A.4.1.1.10 | E42: =Analisa!D466 -> Membuat 1 m3 beton mutu f'c = 26,4 MPa (K 300) slump (12±2) cm w/c = 0,52 | F42: Rp. | G42: =Analisa!N482 -> 1225084
A43: =Analisa!A484 -> 32 | B43: =Analisa!B484 -> A.4.1.1.12 | E43: =Analisa!D484 -> Membuat 1 m3 beton mutu f'c = 31,2 MPa (K 350) slump (12±2) cm w/c = 0,48 | F43: Rp. | G43: =Analisa!N500 -> 1343575
...

Sheet Hit. ME
A1: ANALISA HARGA SATUAN MEKANIKAL DAN ELEKTRIKAL
A5: NO | B5: URAIAN PEKERJAAN | C5: SAT | D5: HSP | E5: Jasa Pasang | F5: Alat Bantu | G5: Harga satuan | H5: KETERANGAN
A7: 1 | B7: KABEL TRAY
B8: Alat bantu & penunjang | C8: % | H8: 2
B9: Jasa pasang & instalasi | C9: % | H9: 3.5
B10: ='[141]00-INSTALASI (2)'!$A$11 -> Keuntungan+Over head | C10: % | H10: 10
B11: Weist | C11: % | H11: 1.5
B13: Kabel Tray :
B14: ▪ Kabel Tray, uk. 100 mm x 100 mm | C14: m' | D14: =SUM(E14:G14)*(1+($H$10/100)) -> 212371.5 | E14: =(G14*$H$9)/100 -> 6405 | F14: =(G14*$H$8)/100 -> 3660 | G14: 183000
B15: ▪ Kabel Tray, uk. 150 mm x 100 mm | C15: m' | D15: =SUM(E15:G15)*(1+($H$10/100)) -> 225137 | E15: =(G15*$H$9)/100 -> 6790 | F15: =(G15*$H$8)/100 -> 3880 | G15: 194000
B16: ▪ Kabel Tray, uk. 200 mm x 100 mm | C16: m' | D16: =SUM(E16:G16)*(1+($H$10/100)) -> 238289.33 | E16: =(G16*$H$9)/100 -> 7186.6667 | F16: =(G16*$H$8)/100 -> 4106.6667 | G16: =[142]BAHAN!G783 -> 205333.33
B17: ▪ Kabel Tray, uk. 300 mm x 100 mm | C17: m' | D17: =SUM(E17:G17)*(1+($H$10/100)) -> 297861.67 | E17: =(G17*$H$9)/100 -> 8983.3333 | F17: =(G17*$H$8)/100 -> 5133.3333 | G17: =[142]BAHAN!G784 -> 256666.67
B18: ▪ Kabel Tray, uk. 400 mm x 100 mm | C18: m' | D18: =SUM(E18:G18)*(1+($H$10/100)) -> 357434 | E18: =(G18*$H$9)/100 -> 10780 | F18: =(G18*$H$8)/100 -> 6160 | G18: =[142]BAHAN!G785 -> 308000
B19: ▪ Kabel Tray, uk. 500 mm x 100 mm | C19: m' | D19: =SUM(E19:G19)*(1+($H$10/100)) -> 476965.5 | E19: =(G19*$H$9)/100 -> 14385 | F19: =(G19*$H$8)/100 -> 8220 | G19: 411000
B20: ▪ Kabel Tray, uk. 600 mm x 100 mm | C20: m' | D20: =SUM(E20:G20)*(1+($H$10/100)) -> 546595.5 | E20: =(G20*$H$9)/100 -> 16485 | F20: =(G20*$H$8)/100 -> 9420 | G20: 471000
B21: ▪ Kabel Tray, uk. 700 mm x 100 mm | C21: m' | D21: =SUM(E21:G21)*(1+($H$10/100)) -> 706744.5 | E21: =(G21*$H$9)/100 -> 21315 | F21: =(G21*$H$8)/100 -> 12180 | G21: 609000
B22: ▪ Kabel Tray, uk. 800 mm x 100 mm | C22: m' | D22: =SUM(E22:G22)*(1+($H$10/100)) -> 754325 | E22: =(G22*$H$9)/100 -> 22750 | F22: =(G22*$H$8)/100 -> 13000 | G22: 650000
B23: ▪ Kabel Tray, uk. 900 mm x 100 mm | C23: m' | D23: =SUM(E23:G23)*(1+($H$10/100)) -> 928400 | E23: =(G23*$H$9)/100 -> 28000 | F23: =(G23*$H$8)/100 -> 16000 | G23: 800000
B24: ▪ Kabel Tray, uk. 1000 mm x 100 mm | C24: m' | D24: =SUM(E24:G24)*(1+($H$10/100)) -> 1102475 | E24: =(G24*$H$9)/100 -> 33250 | F24: =(G24*$H$8)/100 -> 19000 | G24: 950000
B26: ▪ Kabel Tray, uk. 100 mm x 50 mm | C26: m' | D26: =SUM(E26:G26)*(1+($H$10/100)) -> 198445.5 | E26: =(G26*$H$9)/100 -> 5985 | F26: =(G26*$H$8)/100 -> 3420 | G26: 171000
B27: ▪ Kabel Tray, uk. 150 mm x 50 mm | C27: m' | D27: =SUM(E27:G27)*(1+($H$10/100)) -> 221655.5 | E27: =(G27*$H$9)/100 -> 6685 | F27: =(G27*$H$8)/100 -> 3820 | G27: 191000
B28: ▪ Kabel Tray, uk. 200 mm x 50 mm | C28: m' | D28: =SUM(E28:G28)*(1+($H$10/100)) -> 246026 | E28: =(G28*$H$9)/100 -> 7420 | F28: =(G28*$H$8)/100 -> 4240 | G28: 212000
B29: ▪ Kabel Tray, uk. 300 mm x 50 mm | C29: m' | D29: =SUM(E29:G29)*(1+($H$10/100)) -> 308693 | E29: =(G29*$H$9)/100 -> 9310 | F29: =(G29*$H$8)/100 -> 5320 | G29: 266000
B30: ▪ Kabel Tray, uk. 400 mm x 50 mm | C30: m' | D30: =SUM(E30:G30)*(1+($H$10/100)) -> 358594.5 | E30: =(G30*$H$9)/100 -> 10815 | F30: =(G30*$H$8)/100 -> 6180 | G30: 309000
B31: ▪ Kabel Tray, uk. 500 mm x 50 mm | C31: m' | D31: =SUM(E31:G31)*(1+($H$10/100)) -> 424743 | E31: =(G31*$H$9)/100 -> 12810 | F31: =(G31*$H$8)/100 -> 7320 | G31: 366000
... B34: ▪ Kabel Tray, uk. 800 mm x 50 mm | C34: m' | D34: =SUM(E34:G34)*(1+($H$10/100)) -> 706744.5 | E34: =(G34*$H$9)/100 -> 21315 | F34: =(G34*$H$8)/100 -> 12180 | G34: 609000
B36: Kabel Ladder :
B37: ▪ Kabel Tray, uk. 100 mm x 100 mm | C37: m' | D37: =SUM(E37:G37)*(1+($H$10/100)) -> 232100 | E37: =(G37*$H$9)/100 -> 7000 | F37: =(G37*$H$8)/100 -> 4000 | G37: 200000
B38: ▪ Kabel Tray, uk. 150 mm x 100 mm | C38: m' | D38: =SUM(E38:G38)*(1+($H$10/100)) -> 170187.33 | E38: =(G38*$H$9)/100 -> 5132.75 | F38: =(G38*$H$8)/100 -> 2933 | G38: =G40*0.7 -> 146650
B39: ▪ Kabel Tray, uk. 200 mm x 100 mm | C39: m' | D39: =SUM(E39:G39)*(1+($H$10/100)) -> 194499.8 | E39: =(G39*$H$9)/100 -> 5866 | F39: =(G39*$H$8)/100 -> 3352 | G39: 167600
B40: ▪ Kabel Tray, uk. 300 mm x 100 mm | C40: m' | D40: =SUM(E40:G40)*(1+($H$10/100)) -> 243124.75 | E40: =(G40*$H$9)/100 -> 7332.5 | F40: =(G40*$H$8)/100 -> 4190 | G40: 209500
B41: ▪ Kabel Tray, uk. 400 mm x 100 mm | C41: m' | D41: =SUM(E41:G41)*(1+($H$10/100)) -> 406175 | E41: =(G41*$H$9)/100 -> 12250 | F41: =(G41*$H$8)/100 -> 7000 | G41: 350000
B42: ▪ Kabel Tray, uk. 500 mm x 100 mm | C42: m' | D42: =SUM(E42:G42)*(1+($H$10/100)) -> 438669 | E42: =(G42*$H$9)/100 -> 13230 | F42: =(G42*$H$8)/100 -> 7560 | G42: 378000
B43: ▪ Kabel Tray, uk. 600 mm x 100 mm | C43: m' | D43: =SUM(E43:G43)*(1+($H$10/100)) -> 467681.5 | E43: =(G43*$H$9)/100 -> 14105 | F43: =(G43*$H$8)/100 -> 8060 | G43: 403000
B44: ▪ Kabel Tray, uk. 700 mm x 100 mm | C44: m' | D44: =SUM(E44:G44)*(1+($H$10/100)) -> 467681.5 | E44: =(G44*$H$9)/100 -> 14105 | F44: =(G44*$H$8)/100 -> 8060 | G44: 403000
B45: ▪ Kabel Tray, uk. 800 mm x 100 mm | C45: m' | D45: =SUM(E45:G45)*(1+($H$10/100)) -> 540793 | E45: =(G45*$H$9)/100 -> 16310 | F45: =(G45*$H$8)/100 -> 9320 | G45: 466000
B47: KABEL BCC
B48: BCC 6 mm2 (0,06 kg/m) | C48: m' | D48: =SUM(E48:G48)*(1+($H$10/100)) -> 17987.75 | E48: =(G48*$H$9)/100 -> 542.5 | F48: =(G48*$H$8)/100 -> 310 | G48: 15500
B49: BCC 10 mm2 (0,10 kg/m) | C49: m' | D49: =SUM(E49:G49)*(1+($H$10/100)) -> 23442.1 | E49: =(G49*$H$9)/100 -> 707 | F49: =(G49*$H$8)/100 -> 404 | G49: 20200
B50: BCC 16 mm2 (0,16 kg/m) | C50: m' | D50: =SUM(E50:G50)*(1+($H$10/100)) -> 30056.95 | E50: =(G50*$H$9)/100 -> 906.5 | F50: =(G50*$H$8)/100 -> 518 | G50: 25900
...

Sheet Analisa
F1: Pemasangan alumunium Frame Daun Jendela Kaca Powder Coating
A2: ANALISA SATUAN PEKERJAAN BANGUNAN
A3: =Bahan!A3 -> TAHUN 2025
P4: Overhead = | Q4: 0.1
A6: No | D6: Koefisien | E6: Satuan | F6: Uraian | H6: Harga Satuan | L6: Jumlah | N6: Jumlah
L7: Harga | N7: Total
H8: (Rp) | L8: (Rp) | N8: (Rp)
A10: A | B10: A.2.2.1 | D10: HARGA SATUAN PEKERJAAN PERSIAPAN
A12: 1 | B12: A.2.2.1.2 | C12: a | D12: Pembuatan 1 m' pagar sementara dari seng gelombang tinggi 2 m'
E13: A | F13: TENAGA KERJA
D14: 0.2 | E14: OH | F14: Pekerja | G14: @Rp. | H14: =Bahan!$C$10 -> 125000 | K14: Rp. | L14: =D14*H14 -> 25000
D15: 0.4 | E15: OH | F15: Tukang Kayu | G15: @Rp. | H15: =Bahan!$C$11 -> 135000 | K15: Rp. | L15: =D15*H15 -> 54000
D16: 0.02 | E16: OH | F16: Kepala Tukang | G16: @Rp. | H16: =Bahan!$C$21 -> 145000 | K16: Rp. | L16: =D16*H16 -> 2900
D17: 0.02 | E17: OH | F17: Mandor | G17: @Rp. | H17: =Bahan!$C$22 -> 150000 | K17: Rp. | L17: =D17*H17 -> 3000
M18: Rp. | N18: =SUM(L14:L17) -> 84900
E19: B | F19: BAHAN
D20: 1.25 | E20: batang | F20: Bambu | G20: @Rp. | H20: =Bahan!C27 -> 12500 | K20: Rp. | L20: =D20*H20 -> 15625
D21: 1.2 | E21: Lbr | F21: Seng gelombang 3" - 5 " | G21: @Rp. | H21: =Bahan!$C$131 -> 118500 | K21: Rp. | L21: =D21*H21 -> 142200
D22: 0.072 | E22: m3 | F22: Kayu Klas III | G22: @Rp. | H22: =Bahan!C28 -> 1500000 | K22: Rp. | L22: =D22*H22 -> 108000
D23: 0.06 | E23: kg | F23: Paku | G23: @Rp. | H23: =Bahan!$C$25 -> 15000 | K23: Rp. | L23: =D23*H23 -> 900
D24: 2.5 | E24: kg | F24: Portland cement | G24: @Rp. | H24: =Bahan!$C$31 -> 1250 | K24: Rp. | L24: =D24*H24 -> 3125
D25: 0.009 | E25: m³ | F25: Koral beton | G25: @Rp. | H25: =Bahan!C47 -> 280000 | K25: Rp. | L25: =D25*H25 -> 2520
D26: 0.009 | E26: m³ | F26: Pasir beton (quarry - lokasi pekerjaan) | G26: @Rp. | H26: =Bahan!$C$43 -> 245000 | K26: Rp. | L26: =D26*H26 -> 2205
M27: Rp. | N27: =SUM(L20:L26) -> 274575
M28: = | N28: =
H29: Jumlah Total | M29: Rp. | N29: =SUM(N18:N27) -> 359475
H30: Overhead & Profit (10% ) | M30: Rp. | N30: =N29*$Q$4 -> 35947.5
H31: Total Harga Satuan Pekerjaan | M31: Rp. | N31: =ROUNDDOWN((N29+N30),0) -> 395422
B33: A.2.2.1.2a | C33: b | D33: Pembuatan 1 m' pagar sementara dari seng gelombang tinggi 2 m' (sewa) | G33: @Rp. | H33: =N31 -> 395422 | I33: : | J33: 1.2
M34: Rp. | N34: =H33/J33 -> 329518.33
A37: =A12+1 -> 2 | B37: A.2.2.1.4 | D37: Pengukuran dan pemasangan 1 m' Bouwplank
F38: TENAGA KERJA
D39: 0.1 | E39: OH | F39: Pekerja | G39: @Rp. | H39: =Bahan!$C$10 -> 125000 | K39: Rp. | L39: =D39*H39 -> 12500
D40: 0.1 | E40: OH | F40: Tukang Kayu | G40: @Rp. | H40: =Bahan!$C$11 -> 135000 | K40: Rp. | L40: =D40*H40 -> 13500
D41: 0.01 | E41: OH | F41: Kepala Tukang | G41: @Rp. | H41: =Bahan!$C$21 -> 145000 | K41: Rp. | L41: =D41*H41 -> 1450
D42: 0.005 | E42: OH | F42: Mandor | G42: @Rp. | H42: =Bahan!$C$22 -> 150000 | K42: Rp. | L42: =D42*H42 -> 750
M43: Rp. | N43: =SUM(L39:L42) -> 28200
F44: BAHAN
D45: 0.012 | E45: m3 | F45: Kayu Klas III utk bowplank,pagar dan kantor sementara | G45: @Rp. | H45: =Bahan!C28 -> 1500000 | K45: Rp. | L45: =D45*H45 -> 18000
D46: 0.02 | E46: kg | F46: Paku | G46: @Rp. | H46: =Bahan!C25 -> 15000 | K46: Rp. | L46: =D46*H46 -> 300
...

Sheet Bahan MEP
B9: ACB 5000 AT/5000 AF/100 kA/4P | F9: =327600000*1 -> 327600000
B10: ACB 1000 A / 4P / 50 kA | F10: 230400000
F11: 0
B12: MCCB 100A/70KA/3P | F12: 3000000
F13: 0
B14: MCCB 63A/50KA/3P | F14: 1840000
B15: MCCB 40A/50KA/3P | F15: 1720000
B16: MCCB 32A/50KA/3P | F16: 1600000
F17: 0
B18: ='RAB GIK UGM'!C494 -> MCCB 630A/36KA/3P | F18: 19750000
B19: MCCB 300A/36KA/3P | F19: 5167600
B20: ='RAB GIK UGM'!C463 -> MCCB 200A/36KA/3P | F20: 3900000
B21: ='RAB GIK UGM'!C412 -> MCCB 160A/36KA/3P | F21: 2900000
B22: ='RAB GIK UGM'!C450 -> MCCB 80A/36KA/3P | F22: 2500000
B23: ='RAB GIK UGM'!C365 -> MCCB 60A/36KA/3P | F23: 2500000
F24: 0
B25: MCCB 32A/25kA/3P | F25: 1680000
F26: 0
B27: ='RAB GIK UGM'!C495 -> MCCB 200A/18KA/3P | F27: 2750000
B28: ='RAB GIK UGM'!C496 -> MCCB 160A/18KA/3P | F28: 2250000
B29: MCCB 100A/18KA/3P | F29: 1750800
B30: MCCB 80A/18KA/3P | F30: 1750800
B31: MCCB 63A/18KA/3P | F31: 1250000
B32: MCCB 60A/18kA/3P | F32: 1250000
B33: MCCB 50A/18kA/3P | F33: 1250000
F34: 0
B35: MCCB 80A/10KA/3P | F35: 600000
F36: 0
B37: MCB 60A/6 KA/3P | F37: 600000
B38: MCB 50 A/6 kA/3P | F38: 600000
B39: MCB 40A/6 KA/3P | F39: 600000
B40: MCB 32A/6 KA/3P | F40: 600000
B41: MCB 25A/6 KA/3P | F41: 600000
B42: MCB 20A/6 KA/3P | F42: 600000
F43: 0
B44: MCB 80A/10 KA/1P | F44: 0
B45: MCB 20A/10 KA/1P | F45: 180000
F46: 0
B47: MCB 60A/6 KA/1P | F47: 155000
B48: MCB 40A/6 KA/1P | F48: 155000
...

Sheet Bahan
A2: HARGA BAHAN
A3: TAHUN 2025
A5: No | B5: Bahan / Upah Tenaga | C5: Harga Bahan (Rp) | D5: Satuan
A9: I. | B9: UPAH PEKERJA
A10: 1 | B10: Pekerja | C10: 125000 | D10: OH | F10: 2655041.8 | G10: =F10/25 -> 106201.67
A11: =A10+1 -> 2 | B11: Tukang Kayu | C11: =$C$10+10000 -> 135000 | D11: OH | G11: =G10*1.065 -> 113104.78
A12: =A11+1 -> 3 | B12: Tukang Batu | C12: =$C$10+10000 -> 135000 | D12: OH
A13: =A12+1 -> 4 | B13: Tukang besi | C13: =$C$10+10000 -> 135000 | D13: OH
A14: =A13+1 -> 5 | B14: Tukang las konstruksi | C14: =$C$10+10000 -> 135000 | D14: OH
A15: =A14+1 -> 6 | B15: Tukang besi konstruksi | C15: =$C$10+10000 -> 135000 | D15: OH
A16: =A15+1 -> 7 | B16: Tukang las biasa | C16: =$C$10+10000 -> 135000 | D16: OH
A17: =A16+1 -> 8 | B17: Tukang khusus alumunium | C17: =$C$10+10000 -> 135000 | D17: OH
A18: =A17+1 -> 9 | B18: Tukang Pipa | C18: =$C$10+10000 -> 135000 | D18: OH
A19: =A18+1 -> 10 | B19: Tukang cat | C19: =$C$10+10000 -> 135000 | D19: OH
A20: =A19+1 -> 11 | B20: Tukang listrik | C20: =$C$10+10000 -> 135000 | D20: OH
A21: =A20+1 -> 12 | B21: Kepala Tukang | C21: =$C$10+20000 -> 145000 | D21: OH
A22: =A21+1 -> 13 | B22: Mandor | C22: =$C$10+25000 -> 150000 | D22: OH
A24: II. | B24: HARGA BAHAN
A25: =A22+1 -> 14 | B25: Paku | C25: 15000 | D25: kg
A26: =A25+1 -> 15 | B26: Dolken kayu diameter 8-10/400 cm | C26: 12500 | D26: batang
A27: =A26+1 -> 16 | B27: Bambu | C27: 12500 | D27: batang
A28: =A27+1 -> 17 | B28: Kayu Klas III / begesting | C28: 1500000 | D28: m3
A29: =A28+1 -> 18 | B29: Balok Kayu Klas II | C29: 2450000 | D29: m3
A30: =A29+1 -> 19 | B30: Portland cement 40 kg | C30: 50000 | D30: zak
B31: Portland cement | C31: =C30/40 -> 1250 | D31: kg
A32: =A30+1 -> 20 | B32: Bata merah | C32: 1350 | D32: Bh
A33: =A32+1 -> 21 | B33: bata tahan api 230 x 114 x 65 | C33: 3000 | D33: Bh
A34: =A33+1 -> 22 | B34: Semen pasangan bata tahan api @ 25 kg | C34: 325000 | D34: zak
A35: =A34+1 -> 23 | B35: Bata ringan ( fast con ) 20x60 cm tebal 10 mm | C35: =730000/84 -> 8690.4762 | D35: Bh | G35: =C35*83 -> 721309.52
A36: =A35+1 -> 24 | B36: Perekat bata ringan | C36: =(85000*1.05)/40 -> 2231.25 | D36: kg
A37: =A36+1 -> 25 | B37: Plester bata ringan | C37: 130000 | D37: zak
A38: =A37+1 -> 26 | B38: Semen mortar warna abu (Acian bata ringan) | C38: =(72500*1) -> 72500 | D38: zak
A39: =A38+1 -> 27 | B39: Semen skimcoat | C39: =150000 -> 150000 | D39: zak
A40: =A39+1 -> 28 | B40: Sirtu | C40: =C41 -> 190000 | D40: m3
A41: =A40+1 -> 29 | B41: Pasir urug | C41: 190000 | D41: m3
A42: =A41+1 -> 30 | B42: Pasir pasang | C42: 215000 | D42: m3
A43: =A42+1 -> 31 | B43: Pasir beton | C43: 245000 | D43: m3
A44: =A43+1 -> 32 | B44: Pasir beton | C44: =C43/1450 -> 168.96552 | D44: kg
A45: =A44+1 -> 33 | B45: Tanah urug | C45: 45000 | D45: m3
A46: =A45+1 -> 34 | B46: Batu belah | C46: 215000 | D46: m3
...

Sheet TKDN
A4: FORMULIR PENYAMPAIAN
A5: TINGKAT KOMPONEN DALAM NEGERI (TKDN)
A7: NAMA PENYEDIA | C7: : PT. SINAR CERAH SEMPURNA
A8: ='REKAP Tot'!A4 -> Pekerjaan | C8: ='REKAP Tot'!C4 -> : Pembangunan Gedung Gelanggang Inovasi dan Kreativitas (GIK) UGM Tahap II
A9: ='REKAP Tot'!A5 -> Lokasi | C9: ='REKAP Tot'!C5 -> : Jl. Pancasila No. 1, Blimbing Sari, Caturtunggal, Kec. Depok, Kabupaten Sleman, Daerah Istimewa Yogyakarta
A10: ='REKAP Tot'!A6 -> Sumber Dana | C10: ='REKAP Tot'!C6 -> : APBN
A11: ='REKAP Tot'!A7 -> Tahun Anggaran | C11: ='REKAP Tot'!C7 -> : Tahun Jamak (MYC) 2025 - 2026
